Workbook

Sheet 销售数据明细
A1: 2024年电商销售数据明细
A2: 订单ID | B2: 订单日期 | C2: 店铺名称 | D2: 商品分类 | E2: 商品名称 | F2: 销售数量 | G2: 单价(元) | H2: 销售金额(元) | I2: 成本金额(元) | J2: 利润(元) | K2: 利润率
A3: ORD000001 | B3: 45364 | C3: 折扣专营店 | D3: 美妆个护 | E3: 沐浴露 | F3: 8 | G3: 4943 | H3: =F3*G3 | I3: =H3*0.32 | J3: =H3-I3 | K3: =IFERROR(J3/H3,0)
A4: ORD000002 | B4: 45628 | C4: 跨境电商店 | D4: 美妆个护 | E4: 面膜 | F4: 2 | G4: 1670.19 | H4: =F4*G4 | I4: =H4*0.36 | J4: =H4-I4 | K4: =IFERROR(J4/H4,0)
A5: ORD000003 | B5: 45368 | C5: 折扣专营店 | D5: 食品生鲜 | E5: 牛奶 | F5: 5 | G5: 2435.99 | H5: =F5*G5 | I5: =H5*0.65 | J5: =H5-I5 | K5: =IFERROR(J5/H5,0)
A6: ORD000004 | B6: 45380 | C6: 品牌专卖店 | D6: 家居生活 | E6: 保温杯 | F6: 2 | G6: 2184.41 | H6: =F6*G6 | I6: =H6*0.36 | J6: =H6-I6 | K6: =IFERROR(J6/H6,0)
A7: ORD000005 | B7: 45328 | C7: 官方旗舰店 | D7: 服饰鞋包 | E7: 连衣裙 | F7: 2 | G7: 929.79 | H7: =F7*G7 | I7: =H7*0.5 | J7: =H7-I7 | K7: =IFERROR(J7/H7,0)
A8: ORD000006 | B8: 45460 | C8: 跨境电商店 | D8: 服饰鞋包 | E8: 休闲卫衣 | F8: 2 | G8: 2997.34 | H8: =F8*G8 | I8: =H8*0.62 | J8: =H8-I8 | K8: =IFERROR(J8/H8,0)
A9: ORD000007 | B9: 45351 | C9: 跨境电商店 | D9: 家居生活 | E9: 收纳箱 | F9: 9 | G9: 3900.45 | H9: =F9*G9 | I9: =H9*0.65 | J9: =H9-I9 | K9: =IFERROR(J9/H9,0)
A10: ORD000008 | B10: 45371 | C10: 官方旗舰店 | D10: 家居生活 | E10: 空气净化器 | F10: 1 | G10: 3717.06 | H10: =F10*G10 | I10: =H10*0.58 | J10: =H10-I10 | K10: =IFERROR(J10/H10,0)
A11: ORD000009 | B11: 45517 | C11: 跨境电商店 | D11: 3C数码 | E11: 平板电脑 | F11: 5 | G11: 2825.38 | H11: =F11*G11 | I11: =H11*0.43 | J11: =H11-I11 | K11: =IFERROR(J11/H11,0)
A12: ORD000010 | B12: 45356 | C12: 品牌专卖店 | D12: 家居生活 | E12: 床上四件套 | F12: 3 | G12: 2182.09 | H12: =F12*G12 | I12: =H12*0.68 | J12: =H12-I12 | K12: =IFERROR(J12/H12,0)
A13: ORD000011 | B13: 45635 | C13: 跨境电商店 | D13: 食品生鲜 | E13: 肉类生鲜 | F13: 10 | G13: 764.7 | H13: =F13*G13 | I13: =H13*0.36 | J13: =H13-I13 | K13: =IFERROR(J13/H13,0)
A14: ORD000012 | B14: 45345 | C14: 品牌专卖店 | D14: 3C数码 | E14: 智能手表 | F14: 1 | G14: 1571.88 | H14: =F14*G14 | I14: =H14*0.56 | J14: =H14-I14 | K14: =IFERROR(J14/H14,0)
A15: ORD000013 | B15: 45656 | C15: 品牌专卖店 | D15: 3C数码 | E15: 智能手机 | F15: 8 | G15: 2997.43 | H15: =F15*G15 | I15: =H15*0.68 | J15: =H15-I15 | K15: =IFERROR(J15/H15,0)
A16: ORD000014 | B16: 45388 | C16: 品牌专卖店 | D16: 家居生活 | E16: 空气净化器 | F16: 4 | G16: 248.96 | H16: =F16*G16 | I16: =H16*0.66 | J16: =H16-I16 | K16: =IFERROR(J16/H16,0)
A17: ORD000015 | B17: 45589 | C17: 折扣专营店 | D17: 服饰鞋包 | E17: 运动鞋 | F17: 8 | G17: 2813.8 | H17: =F17*G17 | I17: =H17*0.38 | J17: =H17-I17 | K17: =IFERROR(J17/H17,0)
A18: ORD000016 | B18: 45494 | C18: 品牌专卖店 | D18: 3C数码 | E18: 平板电脑 | F18: 3 | G18: 1956.23 | H18: =F18*G18 | I18: =H18*0.68 | J18: =H18-I18 | K18: =IFERROR(J18/H18,0)
A19: ORD000017 | B19: 45358 | C19: 官方旗舰店 | D19: 食品生鲜 | E19: 肉类生鲜 | F19: 9 | G19: 408.56 | H19: =F19*G19 | I19: =H19*0.68 | J19: =H19-I19 | K19: =IFERROR(J19/H19,0)
A20: ORD000018 | B20: 45461 | C20: 折扣专营店 | D20: 家居生活 | E20: 保温杯 | F20: 3 | G20: 1531.4 | H20: =F20*G20 | I20: =H20*0.38 | J20: =H20-I20 | K20: =IFERROR(J20/H20,0)
A21: ORD000019 | B21: 45478 | C21: 跨境电商店 | D21: 3C数码 | E21: 笔记本电脑 | F21: 8 | G21: 873.05 | H21: =F21*G21 | I21: =H21*0.44 | J21: =H21-I21 | K21: =IFERROR(J21/H21,0)
A22: ORD000020 | B22: 45566 | C22: 折扣专营店 | D22: 美妆个护 | E22: 洗发水 | F22: 8 | G22: 4180.37 | H22: =F22*G22 | I22: =H22*0.48 | J22: =H22-I22 | K22: =IFERROR(J22/H22,0)
A23: ORD000021 | B23: 45547 | C23: 折扣专营店 | D23: 美妆个护 | E23: 粉底液 | F23: 9 | G23: 127.92 | H23: =F23*G23 | I23: =H23*0.33 | J23: =H23-I23 | K23: =IFERROR(J23/H23,0)
A24: ORD000022 | B24: 45483 | C24: 跨境电商店 | D24: 3C数码 | E24: 平板电脑 | F24: 4 | G24: 1194.65 | H24: =F24*G24 | I24: =H24*0.58 | J24: =H24-I24 | K24: =IFERROR(J24/H24,0)
A25: ORD000023 | B25: 45641 | C25: 品牌专卖店 | D25: 3C数码 | E25: 智能手表 | F25: 7 | G25: 3730.78 | H25: =F25*G25 | I25: =H25*0.31 | J25: =H25-I25 | K25: =IFERROR(J25/H25,0)
A26: ORD000024 | B26: 45314 | C26: 折扣专营店 | D26: 3C数码 | E26: 笔记本电脑 | F26: 10 | G26: 3708.02 | H26: =F26*G26 | I26: =H26*0.49 | J26: =H26-I26 | K26: =IFERROR(J26/H26,0)
A27: ORD000025 | B27: 45586 | C27: 官方旗舰店 | D27: 家居生活 | E27: 扫地机器人 | F27: 10 | G27: 4168.12 | H27: =F27*G27 | I27: =H27*0.46 | J27: =H27-I27 | K27: =IFERROR(J27/H27,0)
A28: ORD000026 | B28: 45340 | C28: 官方旗舰店 | D28: 服饰鞋包 | E28: 牛仔裤 | F28: 4 | G28: 4143.81 | H28: =F28*G28 | I28: =H28*0.46 | J28: =H28-I28 | K28: =IFERROR(J28/H28,0)
A29: ORD000027 | B29: 45544 | C29: 折扣专营店 | D29: 3C数码 | E29: 笔记本电脑 | F29: 8 | G29: 1419.36 | H29: =F29*G29 | I29: =H29*0.45 | J29: =H29-I29 | K29: =IFERROR(J29/H29,0)
A30: ORD000028 | B30: 45657 | C30: 官方旗舰店 | D30: 家居生活 | E30: 床上四件套 | F30: 1 | G30: 865.32 | H30: =F30*G30 | I30: =H30*0.46 | J30: =H30-I30 | K30: =IFERROR(J30/H30,0)
A31: ORD000029 | B31: 45450 | C31: 折扣专营店 | D31: 家居生活 | E31: 床上四件套 | F31: 4 | G31: 3452.79 | H31: =F31*G31 | I31: =H31*0.7 | J31: =H31-I31 | K31: =IFERROR(J31/H31,0)
A32: ORD000030 | B32: 45406 | C32: 折扣专营店 | D32: 3C数码 | E32: 平板电脑 | F32: 3 | G32: 4684.88 | H32: =F32*G32 | I32: =H32*0.57 | J32: =H32-I32 | K32: =IFERROR(J32/H32,0)
A33: ORD000031 | B33: 45445 | C33: 跨境电商店 | D33: 3C数码 | E33: 笔记本电脑 | F33: 3 | G33: 1514.8 | H33: =F33*G33 | I33: =H33*0.51 | J33: =H33-I33 | K33: =IFERROR(J33/H33,0)
A34: ORD000032 | B34: 45321 | C34: 折扣专营店 | D34: 食品生鲜 | E34: 牛奶 | F34: 5 | G34: 2455.55 | H34: =F34*G34 | I34: =H34*0.49 | J34: =H34-I34 | K34: =IFERROR(J34/H34,0)
A35: ORD000033 | B35: 45638 | C35: 折扣专营店 | D35: 家居生活 | E35: 空气净化器 | F35: 8 | G35: 732.56 | H35: =F35*G35 | I35: =H35*0.4 | J35: =H35-I35 | K35: =IFERROR(J35/H35,0)
A36: ORD000034 | B36: 45528 | C36: 跨境电商店 | D36: 美妆个护 | E36: 面膜 | F36: 5 | G36: 1182.88 | H36: =F36*G36 | I36: =H36*0.54 | J36: =H36-I36 | K36: =IFERROR(J36/H36,0)
A37: ORD000035 | B37: 45408 | C37: 折扣专营店 | D37: 服饰鞋包 | E37: 单肩包 | F37: 10 | G37: 3775.82 | H37: =F37*G37 | I37: =H37*0.42 | J37: =H37-I37 | K37: =IFERROR(J37/H37,0)
A38: ORD000036 | B38: 45407 | C38: 跨境电商店 | D38: 美妆个护 | E38: 沐浴露 | F38: 4 | G38: 4450.29 | H38: =F38*G38 | I38: =H38*0.31 | J38: =H38-I38 | K38: =IFERROR(J38/H38,0)
A39: ORD000037 | B39: 45406 | C39: 跨境电商店 | D39: 3C数码 | E39: 无线耳机 | F39: 7 | G39: 3445.62 | H39: =F39*G39 | I39: =H39*0.4 | J39: =H39-I39 | K39: =IFERROR(J39/H39,0)
A40: ORD000038 | B40: 45485 | C40: 品牌专卖店 | D40: 家居生活 | E40: 扫地机器人 | F40: 2 | G40: 479.14 | H40: =F40*G40 | I40: =H40*0.44 | J40: =H40-I40 | K40: =IFERROR(J40/H40,0)
...

Sheet 月度销售汇总
A1: 2024年月度销售汇总表
A2: 月份 | B2: 店铺名称 | C2: 商品分类 | D2: 总销售数量 | E2: 总销售金额(元) | F2: 总利润(元)
A3: 1月 | B3: 官方旗舰店 | C3: 3C数码 | D3: =SUMIFS('销售数据明细'!$F:$F, '销售数据明细'!$B:$B, ">="&DATE(2024,LEFT(A3,LEN(A3)-1),1), '销售数据明细'!$B:$B, "<="&EOMONTH(DATE(2024,LEFT(A3,LEN(A3)-1),1),0), '销售数据明细'!$C:$C, B3, '销售数据明细'!$D:$D, C3) | E3: =SUMIFS('销售数据明细'!$H:$H, '销售数据明细'!$B:$B, ">="&DATE(2024,LEFT(A3,LEN(A3)-1),1), '销售数据明细'!$B:$B, "<="&EOMONTH(DATE(2024,LEFT(A3,LEN(A3)-1),1),0), '销售数据明细'!$C:$C, B3, '销售数据明细'!$D:$D, C3) | F3: =SUMIFS('销售数据明细'!$J:$J, '销售数据明细'!$B:$B, ">="&DATE(2024,LEFT(A3,LEN(A3)-1),1), '销售数据明细'!$B:$B, "<="&EOMONTH(DATE(2024,LEFT(A3,LEN(A3)-1),1),0), '销售数据明细'!$C:$C, B3, '销售数据明细'!$D:$D, C3)
A4: 1月 | B4: 官方旗舰店 | C4: 家居生活 | D4: =SUMIFS('销售数据明细'!$F:$F, '销售数据明细'!$B:$B, ">="&DATE(2024,LEFT(A4,LEN(A4)-1),1), '销售数据明细'!$B:$B, "<="&EOMONTH(DATE(2024,LEFT(A4,LEN(A4)-1),1),0), '销售数据明细'!$C:$C, B4, '销售数据明细'!$D:$D, C4) | E4: =SUMIFS('销售数据明细'!$H:$H, '销售数据明细'!$B:$B, ">="&DATE(2024,LEFT(A4,LEN(A4)-1),1), '销售数据明细'!$B:$B, "<="&EOMONTH(DATE(2024,LEFT(A4,LEN(A4)-1),1),0), '销售数据明细'!$C:$C, B4, '销售数据明细'!$D:$D, C4) | F4: =SUMIFS('销售数据明细'!$J:$J, '销售数据明细'!$B:$B, ">="&DATE(2024,LEFT(A4,LEN(A4)-1),1), '销售数据明细'!$B:$B, "<="&EOMONTH(DATE(2024,LEFT(A4,LEN(A4)-1),1),0), '销售数据明细'!$C:$C, B4, '销售数据明细'!$D:$D, C4)
A5: 1月 | B5: 官方旗舰店 | C5: 服饰鞋包 | D5: =SUMIFS('销售数据明细'!$F:$F, '销售数据明细'!$B:$B, ">="&DATE(2024,LEFT(A5,LEN(A5)-1),1), '销售数据明细'!$B:$B, "<="&EOMONTH(DATE(2024,LEFT(A5,LEN(A5)-1),1),0), '销售数据明细'!$C:$C, B5, '销售数据明细'!$D:$D, C5) | E5: =SUMIFS('销售数据明细'!$H:$H, '销售数据明细'!$B:$B, ">="&DATE(2024,LEFT(A5,LEN(A5)-1),1), '销售数据明细'!$B:$B, "<="&EOMONTH(DATE(2024,LEFT(A5,LEN(A5)-1),1),0), '销售数据明细'!$C:$C, B5, '销售数据明细'!$D:$D, C5) | F5: =SUMIFS('销售数据明细'!$J:$J, '销售数据明细'!$B:$B, ">="&DATE(2024,LEFT(A5,LEN(A5)-1),1), '销售数据明细'!$B:$B, "<="&EOMONTH(DATE(2024,LEFT(A5,LEN(A5)-1),1),0), '销售数据明细'!$C:$C, B5, '销售数据明细'!$D:$D, C5)
A6: 1月 | B6: 官方旗舰店 | C6: 美妆个护 | D6: =SUMIFS('销售数据明细'!$F:$F, '销售数据明细'!$B:$B, ">="&DATE(2024,LEFT(A6,LEN(A6)-1),1), '销售数据明细'!$B:$B, "<="&EOMONTH(DATE(2024,LEFT(A6,LEN(A6)-1),1),0), '销售数据明细'!$C:$C, B6, '销售数据明细'!$D:$D, C6) | E6: =SUMIFS('销售数据明细'!$H:$H, '销售数据明细'!$B:$B, ">="&DATE(2024,LEFT(A6,LEN(A6)-1),1), '销售数据明细'!$B:$B, "<="&EOMONTH(DATE(2024,LEFT(A6,LEN(A6)-1),1),0), '销售数据明细'!$C:$C, B6, '销售数据明细'!$D:$D, C6) | F6: =SUMIFS('销售数据明细'!$J:$J, '销售数据明细'!$B:$B, ">="&DATE(2024,LEFT(A6,LEN(A6)-1),1), '销售数据明细'!$B:$B, "<="&EOMONTH(DATE(2024,LEFT(A6,LEN(A6)-1),1),0), '销售数据明细'!$C:$C, B6, '销售数据明细'!$D:$D, C6)
A7: 1月 | B7: 官方旗舰店 | C7: 食品生鲜 | D7: =SUMIFS('销售数据明细'!$F:$F, '销售数据明细'!$B:$B, ">="&DATE(2024,LEFT(A7,LEN(A7)-1),1), '销售数据明细'!$B:$B, "<="&EOMONTH(DATE(2024,LEFT(A7,LEN(A7)-1),1),0), '销售数据明细'!$C:$C, B7, '销售数据明细'!$D:$D, C7) | E7: =SUMIFS('销售数据明细'!$H:$H, '销售数据明细'!$B:$B, ">="&DATE(2024,LEFT(A7,LEN(A7)-1),1), '销售数据明细'!$B:$B, "<="&EOMONTH(DATE(2024,LEFT(A7,LEN(A7)-1),1),0), '销售数据明细'!$C:$C, B7, '销售数据明细'!$D:$D, C7) | F7: =SUMIFS('销售数据明细'!$J:$J, '销售数据明细'!$B:$B, ">="&DATE(2024,LEFT(A7,LEN(A7)-1),1), '销售数据明细'!$B:$B, "<="&EOMONTH(DATE(2024,LEFT(A7,LEN(A7)-1),1),0), '销售数据明细'!$C:$C, B7, '销售数据明细'!$D:$D, C7)
A8: 1月 | B8: 品牌专卖店 | C8: 3C数码 | D8: =SUMIFS('销售数据明细'!$F:$F, '销售数据明细'!$B:$B, ">="&DATE(2024,LEFT(A8,LEN(A8)-1),1), '销售数据明细'!$B:$B, "<="&EOMONTH(DATE(2024,LEFT(A8,LEN(A8)-1),1),0), '销售数据明细'!$C:$C, B8, '销售数据明细'!$D:$D, C8) | E8: =SUMIFS('销售数据明细'!$H:$H, '销售数据明细'!$B:$B, ">="&DATE(2024,LEFT(A8,LEN(A8)-1),1), '销售数据明细'!$B:$B, "<="&EOMONTH(DATE(2024,LEFT(A8,LEN(A8)-1),1),0), '销售数据明细'!$C:$C, B8, '销售数据明细'!$D:$D, C8) | F8: =SUMIFS('销售数据明细'!$J:$J, '销售数据明细'!$B:$B, ">="&DATE(2024,LEFT(A8,LEN(A8)-1),1), '销售数据明细'!$B:$B, "<="&EOMONTH(DATE(2024,LEFT(A8,LEN(A8)-1),1),0), '销售数据明细'!$C:$C, B8, '销售数据明细'!$D:$D, C8)
A9: 1月 | B9: 品牌专卖店 | C9: 家居生活 | D9: =SUMIFS('销售数据明细'!$F:$F, '销售数据明细'!$B:$B, ">="&DATE(2024,LEFT(A9,LEN(A9)-1),1), '销售数据明细'!$B:$B, "<="&EOMONTH(DATE(2024,LEFT(A9,LEN(A9)-1),1),0), '销售数据明细'!$C:$C, B9, '销售数据明细'!$D:$D, C9) | E9: =SUMIFS('销售数据明细'!$H:$H, '销售数据明细'!$B:$B, ">="&DATE(2024,LEFT(A9,LEN(A9)-1),1), '销售数据明细'!$B:$B, "<="&EOMONTH(DATE(2024,LEFT(A9,LEN(A9)-1),1),0), '销售数据明细'!$C:$C, B9, '销售数据明细'!$D:$D, C9) | F9: =SUMIFS('销售数据明细'!$J:$J, '销售数据明细'!$B:$B, ">="&DATE(2024,LEFT(A9,LEN(A9)-1),1), '销售数据明细'!$B:$B, "<="&EOMONTH(DATE(2024,LEFT(A9,LEN(A9)-1),1),0), '销售数据明细'!$C:$C, B9, '销售数据明细'!$D:$D, C9)
A10: 1月 | B10: 品牌专卖店 | C10: 服饰鞋包 | D10: =SUMIFS('销售数据明细'!$F:$F, '销售数据明细'!$B:$B, ">="&DATE(2024,LEFT(A10,LEN(A10)-1),1), '销售数据明细'!$B:$B, "<="&EOMONTH(DATE(2024,LEFT(A10,LEN(A10)-1),1),0), '销售数据明细'!$C:$C, B10, '销售数据明细'!$D:$D, C10) | E10: =SUMIFS('销售数据明细'!$H:$H, '销售数据明细'!$B:$B, ">="&DATE(2024,LEFT(A10,LEN(A10)-1),1), '销售数据明细'!$B:$B, "<="&EOMONTH(DATE(2024,LEFT(A10,LEN(A10)-1),1),0), '销售数据明细'!$C:$C, B10, '销售数据明细'!$D:$D, C10) | F10: =SUMIFS('销售数据明细'!$J:$J, '销售数据明细'!$B:$B, ">="&DATE(2024,LEFT(A10,LEN(A10)-1),1), '销售数据明细'!$B:$B, "<="&EOMONTH(DATE(2024,LEFT(A10,LEN(A10)-1),1),0), '销售数据明细'!$C:$C, B10, '销售数据明细'!$D:$D, C10)
A11: 1月 | B11: 品牌专卖店 | C11: 美妆个护 | D11: =SUMIFS('销售数据明细'!$F:$F, '销售数据明细'!$B:$B, ">="&DATE(2024,LEFT(A11,LEN(A11)-1),1), '销售数据明细'!$B:$B, "<="&EOMONTH(DATE(2024,LEFT(A11,LEN(A11)-1),1),0), '销售数据明细'!$C:$C, B11, '销售数据明细'!$D:$D, C11) | E11: =SUMIFS('销售数据明细'!$H:$H, '销售数据明细'!$B:$B, ">="&DATE(2024,LEFT(A11,LEN(A11)-1),1), '销售数据明细'!$B:$B, "<="&EOMONTH(DATE(2024,LEFT(A11,LEN(A11)-1),1),0), '销售数据明细'!$C:$C, B11, '销售数据明细'!$D:$D, C11) | F11: =SUMIFS('销售数据明细'!$J:$J, '销售数据明细'!$B:$B, ">="&DATE(2024,LEFT(A11,LEN(A11)-1),1), '销售数据明细'!$B:$B, "<="&EOMONTH(DATE(2024,LEFT(A11,LEN(A11)-1),1),0), '销售数据明细'!$C:$C, B11, '销售数据明细'!$D:$D, C11)
A12: 1月 | B12: 品牌专卖店 | C12: 食品生鲜 | D12: =SUMIFS('销售数据明细'!$F:$F, '销售数据明细'!$B:$B, ">="&DATE(2024,LEFT(A12,LEN(A12)-1),1), '销售数据明细'!$B:$B, "<="&EOMONTH(DATE(2024,LEFT(A12,LEN(A12)-1),1),0), '销售数据明细'!$C:$C, B12, '销售数据明细'!$D:$D, C12) | E12: =SUMIFS('销售数据明细'!$H:$H, '销售数据明细'!$B:$B, ">="&DATE(2024,LEFT(A12,LEN(A12)-1),1), '销售数据明细'!$B:$B, "<="&EOMONTH(DATE(2024,LEFT(A12,LEN(A12)-1),1),0), '销售数据明细'!$C:$C, B12, '销售数据明细'!$D:$D, C12) | F12: =SUMIFS('销售数据明细'!$J:$J, '销售数据明细'!$B:$B, ">="&DATE(2024,LEFT(A12,LEN(A12)-1),1), '销售数据明细'!$B:$B, "<="&EOMONTH(DATE(2024,LEFT(A12,LEN(A12)-1),1),0), '销售数据明细'!$C:$C, B12, '销售数据明细'!$D:$D, C12)
A13: 1月 | B13: 折扣专营店 | C13: 3C数码 | D13: =SUMIFS('销售数据明细'!$F:$F, '销售数据明细'!$B:$B, ">="&DATE(2024,LEFT(A13,LEN(A13)-1),1), '销售数据明细'!$B:$B, "<="&EOMONTH(DATE(2024,LEFT(A13,LEN(A13)-1),1),0), '销售数据明细'!$C:$C, B13, '销售数据明细'!$D:$D, C13) | E13: =SUMIFS('销售数据明细'!$H:$H, '销售数据明细'!$B:$B, ">="&DATE(2024,LEFT(A13,LEN(A13)-1),1), '销售数据明细'!$B:$B, "<="&EOMONTH(DATE(2024,LEFT(A13,LEN(A13)-1),1),0), '销售数据明细'!$C:$C, B13, '销售数据明细'!$D:$D, C13) | F13: =SUMIFS('销售数据明细'!$J:$J, '销售数据明细'!$B:$B, ">="&DATE(2024,LEFT(A13,LEN(A13)-1),1), '销售数据明细'!$B:$B, "<="&EOMONTH(DATE(2024,LEFT(A13,LEN(A13)-1),1),0), '销售数据明细'!$C:$C, B13, '销售数据明细'!$D:$D, C13)
A14: 1月 | B14: 折扣专营店 | C14: 家居生活 | D14: =SUMIFS('销售数据明细'!$F:$F, '销售数据明细'!$B:$B, ">="&DATE(2024,LEFT(A14,LEN(A14)-1),1), '销售数据明细'!$B:$B, "<="&EOMONTH(DATE(2024,LEFT(A14,LEN(A14)-1),1),0), '销售数据明细'!$C:$C, B14, '销售数据明细'!$D:$D, C14) | E14: =SUMIFS('销售数据明细'!$H:$H, '销售数据明细'!$B:$B, ">="&DATE(2024,LEFT(A14,LEN(A14)-1),1), '销售数据明细'!$B:$B, "<="&EOMONTH(DATE(2024,LEFT(A14,LEN(A14)-1),1),0), '销售数据明细'!$C:$C, B14, '销售数据明细'!$D:$D, C14) | F14: =SUMIFS('销售数据明细'!$J:$J, '销售数据明细'!$B:$B, ">="&DATE(2024,LEFT(A14,LEN(A14)-1),1), '销售数据明细'!$B:$B, "<="&EOMONTH(DATE(2024,LEFT(A14,LEN(A14)-1),1),0), '销售数据明细'!$C:$C, B14, '销售数据明细'!$D:$D, C14)
... A242: 12月 | B242: 跨境电商店 | C242: 食品生鲜 | D242: =SUMIFS('销售数据明细'!$F:$F, '销售数据明细'!$B:$B, ">="&DATE(2024,LEFT(A242,LEN(A242)-1),1), '销售数据明细'!$B:$B, "<="&EOMONTH(DATE(2024,LEFT(A242,LEN(A242)-1),1),0), '销售数据明细'!$C:$C, B242, '销售数据明细'!$D:$D, C242) | E242: =SUMIFS('销售数据明细'!$H:$H, '销售数据明细'!$B:$B, ">="&DATE(2024,LEFT(A242,LEN(A242)-1),1), '销售数据明细'!$B:$B, "<="&EOMONTH(DATE(2024,LEFT(A242,LEN(A242)-1),1),0), '销售数据明细'!$C:$C, B242, '销售数据明细'!$D:$D, C242) | F242: =SUMIFS('销售数据明细'!$J:$J, '销售数据明细'!$B:$B, ">="&DATE(2024,LEFT(A242,LEN(A242)-1),1), '销售数据明细'!$B:$B, "<="&EOMONTH(DATE(2024,LEFT(A242,LEN(A242)-1),1),0), '销售数据明细'!$C:$C, B242, '销售数据明细'!$D:$D, C242)
